Workbook

Sheet Training_Runs
A1: run_id | B1: environment_name | C1: algorithm | D1: learning_rate | E1: batch_size | F1: buffer_size | G1: max_steps | H1: random_seed | I1: cpu_model | J1: has_gpu | K1: ram_gb
B2: =IF(1<=Settings!$C$6, "PushBlock", "") -> PushBlock | C2: =IF(1<=Settings!$C$6, "PPO", "") -> PPO | D2: =IF(1<=Settings!$C$6, IF(Settings!$C$7="Random", CHOOSE(com.sun.star.sheet.addin.Analysis.getRandbetween(1,4), 0.0001, 0.0003, 0.0005, 0.001), 0.0003), "") -> 0.0005 | E2: =IF(1<=Settings!$C$6, IF(Settings!$C$7="Random", CHOOSE(com.sun.star.sheet.addin.Analysis.getRandbetween(1,3), 64, 128, 256), 128), "") -> 256 | F2: =IF(1<=Settings!$C$6, IF(Settings!$C$7="Random", CHOOSE(com.sun.star.sheet.addin.Analysis.getRandbetween(1,3), 1024, 2048, 4096), 2048), "") -> 1024 | G2: =IF(1<=Settings!$C$6, 500000, "") -> 500000 | H2: =IF(1<=Settings!$C$6, IF(Settings!$C$7="Random", CHOOSE(com.sun.star.sheet.addin.Analysis.getRandbetween(1,3), 42, 101, 2024), 42), "") -> 101
B3: =IF(2<=Settings!$C$6, "PushBlock", "") -> PushBlock | C3: =IF(2<=Settings!$C$6, "PPO", "") -> PPO | D3: =IF(2<=Settings!$C$6, IF(Settings!$C$7="Random", CHOOSE(com.sun.star.sheet.addin.Analysis.getRandbetween(1,4), 0.0001, 0.0003, 0.0005, 0.001), 0.0003), "") -> 0.0003 | E3: =IF(2<=Settings!$C$6, IF(Settings!$C$7="Random", CHOOSE(com.sun.star.sheet.addin.Analysis.getRandbetween(1,3), 64, 128, 256), 128), "") -> 64 | F3: =IF(2<=Settings!$C$6, IF(Settings!$C$7="Random", CHOOSE(com.sun.star.sheet.addin.Analysis.getRandbetween(1,3), 1024, 2048, 4096), 2048), "") -> 2048 | G3: =IF(2<=Settings!$C$6, 500000, "") -> 500000 | H3: =IF(2<=Settings!$C$6, IF(Settings!$C$7="Random", CHOOSE(com.sun.star.sheet.addin.Analysis.getRandbetween(1,3), 42, 101, 2024), 42), "") -> 42
B4: =IF(3<=Settings!$C$6, "PushBlock", "") -> PushBlock | C4: =IF(3<=Settings!$C$6, "PPO", "") -> PPO | D4: =IF(3<=Settings!$C$6, IF(Settings!$C$7="Random", CHOOSE(com.sun.star.sheet.addin.Analysis.getRandbetween(1,4), 0.0001, 0.0003, 0.0005, 0.001), 0.0003), "") -> 0.0003 | E4: =IF(3<=Settings!$C$6, IF(Settings!$C$7="Random", CHOOSE(com.sun.star.sheet.addin.Analysis.getRandbetween(1,3), 64, 128, 256), 128), "") -> 128 | F4: =IF(3<=Settings!$C$6, IF(Settings!$C$7="Random", CHOOSE(com.sun.star.sheet.addin.Analysis.getRandbetween(1,3), 1024, 2048, 4096), 2048), "") -> 2048 | G4: =IF(3<=Settings!$C$6, 500000, "") -> 500000 | H4: =IF(3<=Settings!$C$6, IF(Settings!$C$7="Random", CHOOSE(com.sun.star.sheet.addin.Analysis.getRandbetween(1,3), 42, 101, 2024), 42), "") -> 42
B5: =IF(4<=Settings!$C$6, "PushBlock", "") -> PushBlock | C5: =IF(4<=Settings!$C$6, "PPO", "") -> PPO | D5: =IF(4<=Settings!$C$6, IF(Settings!$C$7="Random", CHOOSE(com.sun.star.sheet.addin.Analysis.getRandbetween(1,4), 0.0001, 0.0003, 0.0005, 0.001), 0.0003), "") -> 0.0001 | E5: =IF(4<=Settings!$C$6, IF(Settings!$C$7="Random", CHOOSE(com.sun.star.sheet.addin.Analysis.getRandbetween(1,3), 64, 128, 256), 128), "") -> 128 | F5: =IF(4<=Settings!$C$6, IF(Settings!$C$7="Random", CHOOSE(com.sun.star.sheet.addin.Analysis.getRandbetween(1,3), 1024, 2048, 4096), 2048), "") -> 4096 | G5: =IF(4<=Settings!$C$6, 500000, "") -> 500000 | H5: =IF(4<=Settings!$C$6, IF(Settings!$C$7="Random", CHOOSE(com.sun.star.sheet.addin.Analysis.getRandbetween(1,3), 42, 101, 2024), 42), "") -> 101
B6: =IF(5<=Settings!$C$6, "PushBlock", "") -> PushBlock | C6: =IF(5<=Settings!$C$6, "PPO", "") -> PPO | D6: =IF(5<=Settings!$C$6, IF(Settings!$C$7="Random", CHOOSE(com.sun.star.sheet.addin.Analysis.getRandbetween(1,4), 0.0001, 0.0003, 0.0005, 0.001), 0.0003), "") -> 0.0005 | E6: =IF(5<=Settings!$C$6, IF(Settings!$C$7="Random", CHOOSE(com.sun.star.sheet.addin.Analysis.getRandbetween(1,3), 64, 128, 256), 128), "") -> 128 | F6: =IF(5<=Settings!$C$6, IF(Settings!$C$7="Random", CHOOSE(com.sun.star.sheet.addin.Analysis.getRandbetween(1,3), 1024, 2048, 4096), 2048), "") -> 1024 | G6: =IF(5<=Settings!$C$6, 500000, "") -> 500000 | H6: =IF(5<=Settings!$C$6, IF(Settings!$C$7="Random", CHOOSE(com.sun.star.sheet.addin.Analysis.getRandbetween(1,3), 42, 101, 2024), 42), "") -> 2024
B7: =IF(6<=Settings!$C$6, "PushBlock", "") -> PushBlock | C7: =IF(6<=Settings!$C$6, "PPO", "") -> PPO | D7: =IF(6<=Settings!$C$6, IF(Settings!$C$7="Random", CHOOSE(com.sun.star.sheet.addin.Analysis.getRandbetween(1,4), 0.0001, 0.0003, 0.0005, 0.001), 0.0003), "") -> 0.0003 | E7: =IF(6<=Settings!$C$6, IF(Settings!$C$7="Random", CHOOSE(com.sun.star.sheet.addin.Analysis.getRandbetween(1,3), 64, 128, 256), 128), "") -> 64 | F7: =IF(6<=Settings!$C$6, IF(Settings!$C$7="Random", CHOOSE(com.sun.star.sheet.addin.Analysis.getRandbetween(1,3), 1024, 2048, 4096), 2048), "") -> 1024 | G7: =IF(6<=Settings!$C$6, 500000, "") -> 500000 | H7: =IF(6<=Settings!$C$6, IF(Settings!$C$7="Random", CHOOSE(com.sun.star.sheet.addin.Analysis.getRandbetween(1,3), 42, 101, 2024), 42), "") -> 2024
B8: =IF(7<=Settings!$C$6, "PushBlock", "") -> PushBlock | C8: =IF(7<=Settings!$C$6, "PPO", "") -> PPO | D8: =IF(7<=Settings!$C$6, IF(Settings!$C$7="Random", CHOOSE(com.sun.star.sheet.addin.Analysis.getRandbetween(1,4), 0.0001, 0.0003, 0.0005, 0.001), 0.0003), "") -> 0.001 | E8: =IF(7<=Settings!$C$6, IF(Settings!$C$7="Random", CHOOSE(com.sun.star.sheet.addin.Analysis.getRandbetween(1,3), 64, 128, 256), 128), "") -> 128 | F8: =IF(7<=Settings!$C$6, IF(Settings!$C$7="Random", CHOOSE(com.sun.star.sheet.addin.Analysis.getRandbetween(1,3), 1024, 2048, 4096), 2048), "") -> 1024 | G8: =IF(7<=Settings!$C$6, 500000, "") -> 500000 | H8: =IF(7<=Settings!$C$6, IF(Settings!$C$7="Random", CHOOSE(com.sun.star.sheet.addin.Analysis.getRandbetween(1,3), 42, 101, 2024), 42), "") -> 42
B9: =IF(8<=Settings!$C$6, "PushBlock", "") -> PushBlock | C9: =IF(8<=Settings!$C$6, "PPO", "") -> PPO | D9: =IF(8<=Settings!$C$6, IF(Settings!$C$7="Random", CHOOSE(com.sun.star.sheet.addin.Analysis.getRandbetween(1,4), 0.0001, 0.0003, 0.0005, 0.001), 0.0003), "") -> 0.0003 | E9: =IF(8<=Settings!$C$6, IF(Settings!$C$7="Random", CHOOSE(com.sun.star.sheet.addin.Analysis.getRandbetween(1,3), 64, 128, 256), 128), "") -> 64 | F9: =IF(8<=Settings!$C$6, IF(Settings!$C$7="Random", CHOOSE(com.sun.star.sheet.addin.Analysis.getRandbetween(1,3), 1024, 2048, 4096), 2048), "") -> 4096 | G9: =IF(8<=Settings!$C$6, 500000, "") -> 500000 | H9: =IF(8<=Settings!$C$6, IF(Settings!$C$7="Random", CHOOSE(com.sun.star.sheet.addin.Analysis.getRandbetween(1,3), 42, 101, 2024), 42), "") -> 101
B10: =IF(9<=Settings!$C$6, "PushBlock", "") -> PushBlock | C10: =IF(9<=Settings!$C$6, "PPO", "") -> PPO | D10: =IF(9<=Settings!$C$6, IF(Settings!$C$7="Random", CHOOSE(com.sun.star.sheet.addin.Analysis.getRandbetween(1,4), 0.0001, 0.0003, 0.0005, 0.001), 0.0003), "") -> 0.0003 | E10: =IF(9<=Settings!$C$6, IF(Settings!$C$7="Random", CHOOSE(com.sun.star.sheet.addin.Analysis.getRandbetween(1,3), 64, 128, 256), 128), "") -> 128 | F10: =IF(9<=Settings!$C$6, IF(Settings!$C$7="Random", CHOOSE(com.sun.star.sheet.addin.Analysis.getRandbetween(1,3), 1024, 2048, 4096), 2048), "") -> 1024 | G10: =IF(9<=Settings!$C$6, 500000, "") -> 500000 | H10: =IF(9<=Settings!$C$6, IF(Settings!$C$7="Random", CHOOSE(com.sun.star.sheet.addin.Analysis.getRandbetween(1,3), 42, 101, 2024), 42), "") -> 42
B11: =IF(10<=Settings!$C$6, "PushBlock", "") -> PushBlock | C11: =IF(10<=Settings!$C$6, "PPO", "") -> PPO | D11: =IF(10<=Settings!$C$6, IF(Settings!$C$7="Random", CHOOSE(com.sun.star.sheet.addin.Analysis.getRandbetween(1,4), 0.0001, 0.0003, 0.0005, 0.001), 0.0003), "") -> 0.001 | E11: =IF(10<=Settings!$C$6, IF(Settings!$C$7="Random", CHOOSE(com.sun.star.sheet.addin.Analysis.getRandbetween(1,3), 64, 128, 256), 128), "") -> 128 | F11: =IF(10<=Settings!$C$6, IF(Settings!$C$7="Random", CHOOSE(com.sun.star.sheet.addin.Analysis.getRandbetween(1,3), 1024, 2048, 4096), 2048), "") -> 1024 | G11: =IF(10<=Settings!$C$6, 500000, "") -> 500000 | H11: =IF(10<=Settings!$C$6, IF(Settings!$C$7="Random", CHOOSE(com.sun.star.sheet.addin.Analysis.getRandbetween(1,3), 42, 101, 2024), 42), "") -> 42
B12: =IF(11<=Settings!$C$6, "PushBlock", "") -> PushBlock | C12: =IF(11<=Settings!$C$6, "PPO", "") -> PPO | D12: =IF(11<=Settings!$C$6, IF(Settings!$C$7="Random", CHOOSE(com.sun.star.sheet.addin.Analysis.getRandbetween(1,4), 0.0001, 0.0003, 0.0005, 0.001), 0.0003), "") -> 0.0003 | E12: =IF(11<=Settings!$C$6, IF(Settings!$C$7="Random", CHOOSE(com.sun.star.sheet.addin.Analysis.getRandbetween(1,3), 64, 128, 256), 128), "") -> 256 | F12: =IF(11<=Settings!$C$6, IF(Settings!$C$7="Random", CHOOSE(com.sun.star.sheet.addin.Analysis.getRandbetween(1,3), 1024, 2048, 4096), 2048), "") -> 4096 | G12: =IF(11<=Settings!$C$6, 500000, "") -> 500000 | H12: =IF(11<=Settings!$C$6, IF(Settings!$C$7="Random", CHOOSE(com.sun.star.sheet.addin.Analysis.getRandbetween(1,3), 42, 101, 2024), 42), "") -> 2024
B13: =IF(12<=Settings!$C$6, "PushBlock", "") -> PushBlock | C13: =IF(12<=Settings!$C$6, "PPO", "") -> PPO | D13: =IF(12<=Settings!$C$6, IF(Settings!$C$7="Random", CHOOSE(com.sun.star.sheet.addin.Analysis.getRandbetween(1,4), 0.0001, 0.0003, 0.0005, 0.001), 0.0003), "") -> 0.0005 | E13: =IF(12<=Settings!$C$6, IF(Settings!$C$7="Random", CHOOSE(com.sun.star.sheet.addin.Analysis.getRandbetween(1,3), 64, 128, 256), 128), "") -> 128 | F13: =IF(12<=Settings!$C$6, IF(Settings!$C$7="Random", CHOOSE(com.sun.star.sheet.addin.Analysis.getRandbetween(1,3), 1024, 2048, 4096), 2048), "") -> 1024 | G13: =IF(12<=Settings!$C$6, 500000, "") -> 500000 | H13: =IF(12<=Settings!$C$6, IF(Settings!$C$7="Random", CHOOSE(com.sun.star.sheet.addin.Analysis.getRandbetween(1,3), 42, 101, 2024), 42), "") -> 42
B14: =IF(13<=Settings!$C$6, "PushBlock", "") -> PushBlock | C14: =IF(13<=Settings!$C$6, "PPO", "") -> PPO | D14: =IF(13<=Settings!$C$6, IF(Settings!$C$7="Random", CHOOSE(com.sun.star.sheet.addin.Analysis.getRandbetween(1,4), 0.0001, 0.0003, 0.0005, 0.001), 0.0003), "") -> 0.001 | E14: =IF(13<=Settings!$C$6, IF(Settings!$C$7="Random", CHOOSE(com.sun.star.sheet.addin.Analysis.getRandbetween(1,3), 64, 128, 256), 128), "") -> 128 | F14: =IF(13<=Settings!$C$6, IF(Settings!$C$7="Random", CHOOSE(com.sun.star.sheet.addin.Analysis.getRandbetween(1,3), 1024, 2048, 4096), 2048), "") -> 2048 | G14: =IF(13<=Settings!$C$6, 500000, "") -> 500000 | H14: =IF(13<=Settings!$C$6, IF(Settings!$C$7="Random", CHOOSE(com.sun.star.sheet.addin.Analysis.getRandbetween(1,3), 42, 101, 2024), 42), "") -> 101
B15: =IF(14<=Settings!$C$6, "PushBlock", "") -> PushBlock | C15: =IF(14<=Settings!$C$6, "PPO", "") -> PPO | D15: =IF(14<=Settings!$C$6, IF(Settings!$C$7="Random", CHOOSE(com.sun.star.sheet.addin.Analysis.getRandbetween(1,4), 0.0001, 0.0003, 0.0005, 0.001), 0.0003), "") -> 0.001 | E15: =IF(14<=Settings!$C$6, IF(Settings!$C$7="Random", CHOOSE(com.sun.star.sheet.addin.Analysis.getRandbetween(1,3), 64, 128, 256), 128), "") -> 256 | F15: =IF(14<=Settings!$C$6, IF(Settings!$C$7="Random", CHOOSE(com.sun.star.sheet.addin.Analysis.getRandbetween(1,3), 1024, 2048, 4096), 2048), "") -> 2048 | G15: =IF(14<=Settings!$C$6, 500000, "") -> 500000 | H15: =IF(14<=Settings!$C$6, IF(Settings!$C$7="Random", CHOOSE(com.sun.star.sheet.addin.Analysis.getRandbetween(1,3), 42, 101, 2024), 42), "") -> 101
B16: =IF(15<=Settings!$C$6, "PushBlock", "") -> PushBlock | C16: =IF(15<=Settings!$C$6, "PPO", "") -> PPO | D16: =IF(15<=Settings!$C$6, IF(Settings!$C$7="Random", CHOOSE(com.sun.star.sheet.addin.Analysis.getRandbetween(1,4), 0.0001, 0.0003, 0.0005, 0.001), 0.0003), "") -> 0.0001 | E16: =IF(15<=Settings!$C$6, IF(Settings!$C$7="Random", CHOOSE(com.sun.star.sheet.addin.Analysis.getRandbetween(1,3), 64, 128, 256), 128), "") -> 256 | F16: =IF(15<=Settings!$C$6, IF(Settings!$C$7="Random", CHOOSE(com.sun.star.sheet.addin.Analysis.getRandbetween(1,3), 1024, 2048, 4096), 2048), "") -> 4096 | G16: =IF(15<=Settings!$C$6, 500000, "") -> 500000 | H16: =IF(15<=Settings!$C$6, IF(Settings!$C$7="Random", CHOOSE(com.sun.star.sheet.addin.Analysis.getRandbetween(1,3), 42, 101, 2024), 42), "") -> 101
B17: =IF(16<=Settings!$C$6, "PushBlock", "") -> PushBlock | C17: =IF(16<=Settings!$C$6, "PPO", "") -> PPO | D17: =IF(16<=Settings!$C$6, IF(Settings!$C$7="Random", CHOOSE(com.sun.star.sheet.addin.Analysis.getRandbetween(1,4), 0.0001, 0.0003, 0.0005, 0.001), 0.0003), "") -> 0.0003 | E17: =IF(16<=Settings!$C$6, IF(Settings!$C$7="Random", CHOOSE(com.sun.star.sheet.addin.Analysis.getRandbetween(1,3), 64, 128, 256), 128), "") -> 128 | F17: =IF(16<=Settings!$C$6, IF(Settings!$C$7="Random", CHOOSE(com.sun.star.sheet.addin.Analysis.getRandbetween(1,3), 1024, 2048, 4096), 2048), "") -> 1024 | G17: =IF(16<=Settings!$C$6, 500000, "") -> 500000 | H17: =IF(16<=Settings!$C$6, IF(Settings!$C$7="Random", CHOOSE(com.sun.star.sheet.addin.Analysis.getRandbetween(1,3), 42, 101, 2024), 42), "") -> 2024
B18: =IF(17<=Settings!$C$6, "PushBlock", "") -> PushBlock | C18: =IF(17<=Settings!$C$6, "PPO", "") -> PPO | D18: =IF(17<=Settings!$C$6, IF(Settings!$C$7="Random", CHOOSE(com.sun.star.sheet.addin.Analysis.getRandbetween(1,4), 0.0001, 0.0003, 0.0005, 0.001), 0.0003), "") -> 0.001 | E18: =IF(17<=Settings!$C$6, IF(Settings!$C$7="Random", CHOOSE(com.sun.star.sheet.addin.Analysis.getRandbetween(1,3), 64, 128, 256), 128), "") -> 64 | F18: =IF(17<=Settings!$C$6, IF(Settings!$C$7="Random", CHOOSE(com.sun.star.sheet.addin.Analysis.getRandbetween(1,3), 1024, 2048, 4096), 2048), "") -> 1024 | G18: =IF(17<=Settings!$C$6, 500000, "") -> 500000 | H18: =IF(17<=Settings!$C$6, IF(Settings!$C$7="Random", CHOOSE(com.sun.star.sheet.addin.Analysis.getRandbetween(1,3), 42, 101, 2024), 42), "") -> 2024
B19: =IF(18<=Settings!$C$6, "PushBlock", "") -> PushBlock | C19: =IF(18<=Settings!$C$6, "PPO", "") -> PPO | D19: =IF(18<=Settings!$C$6, IF(Settings!$C$7="Random", CHOOSE(com.sun.star.sheet.addin.Analysis.getRandbetween(1,4), 0.0001, 0.0003, 0.0005, 0.001), 0.0003), "") -> 0.001 | E19: =IF(18<=Settings!$C$6, IF(Settings!$C$7="Random", CHOOSE(com.sun.star.sheet.addin.Analysis.getRandbetween(1,3), 64, 128, 256), 128), "") -> 256 | F19: =IF(18<=Settings!$C$6, IF(Settings!$C$7="Random", CHOOSE(com.sun.star.sheet.addin.Analysis.getRandbetween(1,3), 1024, 2048, 4096), 2048), "") -> 2048 | G19: =IF(18<=Settings!$C$6, 500000, "") -> 500000 | H19: =IF(18<=Settings!$C$6, IF(Settings!$C$7="Random", CHOOSE(com.sun.star.sheet.addin.Analysis.getRandbetween(1,3), 42, 101, 2024), 42), "") -> 42
B20: =IF(19<=Settings!$C$6, "PushBlock", "") -> PushBlock | C20: =IF(19<=Settings!$C$6, "PPO", "") -> PPO | D20: =IF(19<=Settings!$C$6, IF(Settings!$C$7="Random", CHOOSE(com.sun.star.sheet.addin.Analysis.getRandbetween(1,4), 0.0001, 0.0003, 0.0005, 0.001), 0.0003), "") -> 0.001 | E20: =IF(19<=Settings!$C$6, IF(Settings!$C$7="Random", CHOOSE(com.sun.star.sheet.addin.Analysis.getRandbetween(1,3), 64, 128, 256), 128), "") -> 64 | F20: =IF(19<=Settings!$C$6, IF(Settings!$C$7="Random", CHOOSE(com.sun.star.sheet.addin.Analysis.getRandbetween(1,3), 1024, 2048, 4096), 2048), "") -> 4096 | G20: =IF(19<=Settings!$C$6, 500000, "") -> 500000 | H20: =IF(19<=Settings!$C$6, IF(Settings!$C$7="Random", CHOOSE(com.sun.star.sheet.addin.Analysis.getRandbetween(1,3), 42, 101, 2024), 42), "") -> 2024
B21: =IF(20<=Settings!$C$6, "PushBlock", "") -> PushBlock | C21: =IF(20<=Settings!$C$6, "PPO", "") -> PPO | D21: =IF(20<=Settings!$C$6, IF(Settings!$C$7="Random", CHOOSE(com.sun.star.sheet.addin.Analysis.getRandbetween(1,4), 0.0001, 0.0003, 0.0005, 0.001), 0.0003), "") -> 0.0001 | E21: =IF(20<=Settings!$C$6, IF(Settings!$C$7="Random", CHOOSE(com.sun.star.sheet.addin.Analysis.getRandbetween(1,3), 64, 128, 256), 128), "") -> 64 | F21: =IF(20<=Settings!$C$6, IF(Settings!$C$7="Random", CHOOSE(com.sun.star.sheet.addin.Analysis.getRandbetween(1,3), 1024, 2048, 4096), 2048), "") -> 1024 | G21: =IF(20<=Settings!$C$6, 500000, "") -> 500000 | H21: =IF(20<=Settings!$C$6, IF(Settings!$C$7="Random", CHOOSE(com.sun.star.sheet.addin.Analysis.getRandbetween(1,3), 42, 101, 2024), 42), "") -> 2024
B22: =IF(21<=Settings!$C$6, "PushBlock", "") | C22: =IF(21<=Settings!$C$6, "PPO", "") | D22: =IF(21<=Settings!$C$6, IF(Settings!$C$7="Random", CHOOSE(com.sun.star.sheet.addin.Analysis.getRandbetween(1,4), 0.0001, 0.0003, 0.0005, 0.001), 0.0003), "") | E22: =IF(21<=Settings!$C$6, IF(Settings!$C$7="Random", CHOOSE(com.sun.star.sheet.addin.Analysis.getRandbetween(1,3), 64, 128, 256), 128), "") | F22: =IF(21<=Settings!$C$6, IF(Settings!$C$7="Random", CHOOSE(com.sun.star.sheet.addin.Analysis.getRandbetween(1,3), 1024, 2048, 4096), 2048), "") | G22: =IF(21<=Settings!$C$6, 500000, "") | H22: =IF(21<=Settings!$C$6, IF(Settings!$C$7="Random", CHOOSE(com.sun.star.sheet.addin.Analysis.getRandbetween(1,3), 42, 101, 2024), 42), "")
B23: =IF(22<=Settings!$C$6, "PushBlock", "") | C23: =IF(22<=Settings!$C$6, "PPO", "") | D23: =IF(22<=Settings!$C$6, IF(Settings!$C$7="Random", CHOOSE(com.sun.star.sheet.addin.Analysis.getRandbetween(1,4), 0.0001, 0.0003, 0.0005, 0.001), 0.0003), "") | E23: =IF(22<=Settings!$C$6, IF(Settings!$C$7="Random", CHOOSE(com.sun.star.sheet.addin.Analysis.getRandbetween(1,3), 64, 128, 256), 128), "") | F23: =IF(22<=Settings!$C$6, IF(Settings!$C$7="Random", CHOOSE(com.sun.star.sheet.addin.Analysis.getRandbetween(1,3), 1024, 2048, 4096), 2048), "") | G23: =IF(22<=Settings!$C$6, 500000, "") | H23: =IF(22<=Settings!$C$6, IF(Settings!$C$7="Random", CHOOSE(com.sun.star.sheet.addin.Analysis.getRandbetween(1,3), 42, 101, 2024), 42), "")
B24: =IF(23<=Settings!$C$6, "PushBlock", "") | C24: =IF(23<=Settings!$C$6, "PPO", "") | D24: =IF(23<=Settings!$C$6, IF(Settings!$C$7="Random", CHOOSE(com.sun.star.sheet.addin.Analysis.getRandbetween(1,4), 0.0001, 0.0003, 0.0005, 0.001), 0.0003), "") | E24: =IF(23<=Settings!$C$6, IF(Settings!$C$7="Random", CHOOSE(com.sun.star.sheet.addin.Analysis.getRandbetween(1,3), 64, 128, 256), 128), "") | F24: =IF(23<=Settings!$C$6, IF(Settings!$C$7="Random", CHOOSE(com.sun.star.sheet.addin.Analysis.getRandbetween(1,3), 1024, 2048, 4096), 2048), "") | G24: =IF(23<=Settings!$C$6, 500000, "") | H24: =IF(23<=Settings!$C$6, IF(Settings!$C$7="Random", CHOOSE(com.sun.star.sheet.addin.Analysis.getRandbetween(1,3), 42, 101, 2024), 42), "")
B25: =IF(24<=Settings!$C$6, "PushBlock", "") | C25: =IF(24<=Settings!$C$6, "PPO", "") | D25: =IF(24<=Settings!$C$6, IF(Settings!$C$7="Random", CHOOSE(com.sun.star.sheet.addin.Analysis.getRandbetween(1,4), 0.0001, 0.0003, 0.0005, 0.001), 0.0003), "") | E25: =IF(24<=Settings!$C$6, IF(Settings!$C$7="Random", CHOOSE(com.sun.star.sheet.addin.Analysis.getRandbetween(1,3), 64, 128, 256), 128), "") | F25: =IF(24<=Settings!$C$6, IF(Settings!$C$7="Random", CHOOSE(com.sun.star.sheet.addin.Analysis.getRandbetween(1,3), 1024, 2048, 4096), 2048), "") | G25: =IF(24<=Settings!$C$6, 500000, "") | H25: =IF(24<=Settings!$C$6, IF(Settings!$C$7="Random", CHOOSE(com.sun.star.sheet.addin.Analysis.getRandbetween(1,3), 42, 101, 2024), 42), "")
B26: =IF(25<=Settings!$C$6, "PushBlock", "") | C26: =IF(25<=Settings!$C$6, "PPO", "") | D26: =IF(25<=Settings!$C$6, IF(Settings!$C$7="Random", CHOOSE(com.sun.star.sheet.addin.Analysis.getRandbetween(1,4), 0.0001, 0.0003, 0.0005, 0.001), 0.0003), "") | E26: =IF(25<=Settings!$C$6, IF(Settings!$C$7="Random", CHOOSE(com.sun.star.sheet.addin.Analysis.getRandbetween(1,3), 64, 128, 256), 128), "") | F26: =IF(25<=Settings!$C$6, IF(Settings!$C$7="Random", CHOOSE(com.sun.star.sheet.addin.Analysis.getRandbetween(1,3), 1024, 2048, 4096), 2048), "") | G26: =IF(25<=Settings!$C$6, 500000, "") | H26: =IF(25<=Settings!$C$6, IF(Settings!$C$7="Random", CHOOSE(com.sun.star.sheet.addin.Analysis.getRandbetween(1,3), 42, 101, 2024), 42), "")
B27: =IF(26<=Settings!$C$6, "PushBlock", "") | C27: =IF(26<=Settings!$C$6, "PPO", "") | D27: =IF(26<=Settings!$C$6, IF(Settings!$C$7="Random", CHOOSE(com.sun.star.sheet.addin.Analysis.getRandbetween(1,4), 0.0001, 0.0003, 0.0005, 0.001), 0.0003), "") | E27: =IF(26<=Settings!$C$6, IF(Settings!$C$7="Random", CHOOSE(com.sun.star.sheet.addin.Analysis.getRandbetween(1,3), 64, 128, 256), 128), "") | F27: =IF(26<=Settings!$C$6, IF(Settings!$C$7="Random", CHOOSE(com.sun.star.sheet.addin.Analysis.getRandbetween(1,3), 1024, 2048, 4096), 2048), "") | G27: =IF(26<=Settings!$C$6, 500000, "") | H27: =IF(26<=Settings!$C$6, IF(Settings!$C$7="Random", CHOOSE(com.sun.star.sheet.addin.Analysis.getRandbetween(1,3), 42, 101, 2024), 42), "")
B28: =IF(27<=Settings!$C$6, "PushBlock", "") | C28: =IF(27<=Settings!$C$6, "PPO", "") | D28: =IF(27<=Settings!$C$6, IF(Settings!$C$7="Random", CHOOSE(com.sun.star.sheet.addin.Analysis.getRandbetween(1,4), 0.0001, 0.0003, 0.0005, 0.001), 0.0003), "") | E28: =IF(27<=Settings!$C$6, IF(Settings!$C$7="Random", CHOOSE(com.sun.star.sheet.addin.Analysis.getRandbetween(1,3), 64, 128, 256), 128), "") | F28: =IF(27<=Settings!$C$6, IF(Settings!$C$7="Random", CHOOSE(com.sun.star.sheet.addin.Analysis.getRandbetween(1,3), 1024, 2048, 4096), 2048), "") | G28: =IF(27<=Settings!$C$6, 500000, "") | H28: =IF(27<=Settings!$C$6, IF(Settings!$C$7="Random", CHOOSE(com.sun.star.sheet.addin.Analysis.getRandbetween(1,3), 42, 101, 2024), 42), "")
B29: =IF(28<=Settings!$C$6, "PushBlock", "") | C29: =IF(28<=Settings!$C$6, "PPO", "") | D29: =IF(28<=Settings!$C$6, IF(Settings!$C$7="Random", CHOOSE(com.sun.star.sheet.addin.Analysis.getRandbetween(1,4), 0.0001, 0.0003, 0.0005, 0.001), 0.0003), "") | E29: =IF(28<=Settings!$C$6, IF(Settings!$C$7="Random", CHOOSE(com.sun.star.sheet.addin.Analysis.getRandbetween(1,3), 64, 128, 256), 128), "") | F29: =IF(28<=Settings!$C$6, IF(Settings!$C$7="Random", CHOOSE(com.sun.star.sheet.addin.Analysis.getRandbetween(1,3), 1024, 2048, 4096), 2048), "") | G29: =IF(28<=Settings!$C$6, 500000, "") | H29: =IF(28<=Settings!$C$6, IF(Settings!$C$7="Random", CHOOSE(com.sun.star.sheet.addin.Analysis.getRandbetween(1,3), 42, 101, 2024), 42), "")
B30: =IF(29<=Settings!$C$6, "PushBlock", "") | C30: =IF(29<=Settings!$C$6, "PPO", "") | D30: =IF(29<=Settings!$C$6, IF(Settings!$C$7="Random", CHOOSE(com.sun.star.sheet.addin.Analysis.getRandbetween(1,4), 0.0001, 0.0003, 0.0005, 0.001), 0.0003), "") | E30: =IF(29<=Settings!$C$6, IF(Settings!$C$7="Random", CHOOSE(com.sun.star.sheet.addin.Analysis.getRandbetween(1,3), 64, 128, 256), 128), "") | F30: =IF(29<=Settings!$C$6, IF(Settings!$C$7="Random", CHOOSE(com.sun.star.sheet.addin.Analysis.getRandbetween(1,3), 1024, 2048, 4096), 2048), "") | G30: =IF(29<=Settings!$C$6, 500000, "") | H30: =IF(29<=Settings!$C$6, IF(Settings!$C$7="Random", CHOOSE(com.sun.star.sheet.addin.Analysis.getRandbetween(1,3), 42, 101, 2024), 42), "")
B31: =IF(30<=Settings!$C$6, "PushBlock", "") | C31: =IF(30<=Settings!$C$6, "PPO", "") | D31: =IF(30<=Settings!$C$6, IF(Settings!$C$7="Random", CHOOSE(com.sun.star.sheet.addin.Analysis.getRandbetween(1,4), 0.0001, 0.0003, 0.0005, 0.001), 0.0003), "") | E31: =IF(30<=Settings!$C$6, IF(Settings!$C$7="Random", CHOOSE(com.sun.star.sheet.addin.Analysis.getRandbetween(1,3), 64, 128, 256), 128), "") | F31: =IF(30<=Settings!$C$6, IF(Settings!$C$7="Random", CHOOSE(com.sun.star.sheet.addin.Analysis.getRandbetween(1,3), 1024, 2048, 4096), 2048), "") | G31: =IF(30<=Settings!$C$6, 500000, "") | H31: =IF(30<=Settings!$C$6, IF(Settings!$C$7="Random", CHOOSE(com.sun.star.sheet.addin.Analysis.getRandbetween(1,3), 42, 101, 2024), 42), "")
B32: =IF(31<=Settings!$C$6, "PushBlock", "") | C32: =IF(31<=Settings!$C$6, "PPO", "") | D32: =IF(31<=Settings!$C$6, IF(Settings!$C$7="Random", CHOOSE(com.sun.star.sheet.addin.Analysis.getRandbetween(1,4), 0.0001, 0.0003, 0.0005, 0.001), 0.0003), "") | E32: =IF(31<=Settings!$C$6, IF(Settings!$C$7="Random", CHOOSE(com.sun.star.sheet.addin.Analysis.getRandbetween(1,3), 64, 128, 256), 128), "") | F32: =IF(31<=Settings!$C$6, IF(Settings!$C$7="Random", CHOOSE(com.sun.star.sheet.addin.Analysis.getRandbetween(1,3), 1024, 2048, 4096), 2048), "") | G32: =IF(31<=Settings!$C$6, 500000, "") | H32: =IF(31<=Settings!$C$6, IF(Settings!$C$7="Random", CHOOSE(com.sun.star.sheet.addin.Analysis.getRandbetween(1,3), 42, 101, 2024), 42), "")
B33: =IF(32<=Settings!$C$6, "PushBlock", "") | C33: =IF(32<=Settings!$C$6, "PPO", "") | D33: =IF(32<=Settings!$C$6, IF(Settings!$C$7="Random", CHOOSE(com.sun.star.sheet.addin.Analysis.getRandbetween(1,4), 0.0001, 0.0003, 0.0005, 0.001), 0.0003), "") | E33: =IF(32<=Settings!$C$6, IF(Settings!$C$7="Random", CHOOSE(com.sun.star.sheet.addin.Analysis.getRandbetween(1,3), 64, 128, 256), 128), "") | F33: =IF(32<=Settings!$C$6, IF(Settings!$C$7="Random", CHOOSE(com.sun.star.sheet.addin.Analysis.getRandbetween(1,3), 1024, 2048, 4096), 2048), "") | G33: =IF(32<=Settings!$C$6, 500000, "") | H33: =IF(32<=Settings!$C$6, IF(Settings!$C$7="Random", CHOOSE(com.sun.star.sheet.addin.Analysis.getRandbetween(1,3), 42, 101, 2024), 42), "")
B34: =IF(33<=Settings!$C$6, "PushBlock", "") | C34: =IF(33<=Settings!$C$6, "PPO", "") | D34: =IF(33<=Settings!$C$6, IF(Settings!$C$7="Random", CHOOSE(com.sun.star.sheet.addin.Analysis.getRandbetween(1,4), 0.0001, 0.0003, 0.0005, 0.001), 0.0003), "") | E34: =IF(33<=Settings!$C$6, IF(Settings!$C$7="Random", CHOOSE(com.sun.star.sheet.addin.Analysis.getRandbetween(1,3), 64, 128, 256), 128), "") | F34: =IF(33<=Settings!$C$6, IF(Settings!$C$7="Random", CHOOSE(com.sun.star.sheet.addin.Analysis.getRandbetween(1,3), 1024, 2048, 4096), 2048), "") | G34: =IF(33<=Settings!$C$6, 500000, "") | H34: =IF(33<=Settings!$C$6, IF(Settings!$C$7="Random", CHOOSE(com.sun.star.sheet.addin.Analysis.getRandbetween(1,3), 42, 101, 2024), 42), "")
B35: =IF(34<=Settings!$C$6, "PushBlock", "") | C35: =IF(34<=Settings!$C$6, "PPO", "") | D35: =IF(34<=Settings!$C$6, IF(Settings!$C$7="Random", CHOOSE(com.sun.star.sheet.addin.Analysis.getRandbetween(1,4), 0.0001, 0.0003, 0.0005, 0.001), 0.0003), "") | E35: =IF(34<=Settings!$C$6, IF(Settings!$C$7="Random", CHOOSE(com.sun.star.sheet.addin.Analysis.getRandbetween(1,3), 64, 128, 256), 128), "") | F35: =IF(34<=Settings!$C$6, IF(Settings!$C$7="Random", CHOOSE(com.sun.star.sheet.addin.Analysis.getRandbetween(1,3), 1024, 2048, 4096), 2048), "") | G35: =IF(34<=Settings!$C$6, 500000, "") | H35: =IF(34<=Settings!$C$6, IF(Settings!$C$7="Random", CHOOSE(com.sun.star.sheet.addin.Analysis.getRandbetween(1,3), 42, 101, 2024), 42), "")
B36: =IF(35<=Settings!$C$6, "PushBlock", "") | C36: =IF(35<=Settings!$C$6, "PPO", "") | D36: =IF(35<=Settings!$C$6, IF(Settings!$C$7="Random", CHOOSE(com.sun.star.sheet.addin.Analysis.getRandbetween(1,4), 0.0001, 0.0003, 0.0005, 0.001), 0.0003), "") | E36: =IF(35<=Settings!$C$6, IF(Settings!$C$7="Random", CHOOSE(com.sun.star.sheet.addin.Analysis.getRandbetween(1,3), 64, 128, 256), 128), "") | F36: =IF(35<=Settings!$C$6, IF(Settings!$C$7="Random", CHOOSE(com.sun.star.sheet.addin.Analysis.getRandbetween(1,3), 1024, 2048, 4096), 2048), "") | G36: =IF(35<=Settings!$C$6, 500000, "") | H36: =IF(35<=Settings!$C$6, IF(Settings!$C$7="Random", CHOOSE(com.sun.star.sheet.addin.Analysis.getRandbetween(1,3), 42, 101, 2024), 42), "")
B37: =IF(36<=Settings!$C$6, "PushBlock", "") | C37: =IF(36<=Settings!$C$6, "PPO", "") | D37: =IF(36<=Settings!$C$6, IF(Settings!$C$7="Random", CHOOSE(com.sun.star.sheet.addin.Analysis.getRandbetween(1,4), 0.0001, 0.0003, 0.0005, 0.001), 0.0003), "") | E37: =IF(36<=Settings!$C$6, IF(Settings!$C$7="Random", CHOOSE(com.sun.star.sheet.addin.Analysis.getRandbetween(1,3), 64, 128, 256), 128), "") | F37: =IF(36<=Settings!$C$6, IF(Settings!$C$7="Random", CHOOSE(com.sun.star.sheet.addin.Analysis.getRandbetween(1,3), 1024, 2048, 4096), 2048), "") | G37: =IF(36<=Settings!$C$6, 500000, "") | H37: =IF(36<=Settings!$C$6, IF(Settings!$C$7="Random", CHOOSE(com.sun.star.sheet.addin.Analysis.getRandbetween(1,3), 42, 101, 2024), 42), "")
B38: =IF(37<=Settings!$C$6, "PushBlock", "") | C38: =IF(37<=Settings!$C$6, "PPO", "") | D38: =IF(37<=Settings!$C$6, IF(Settings!$C$7="Random", CHOOSE(com.sun.star.sheet.addin.Analysis.getRandbetween(1,4), 0.0001, 0.0003, 0.0005, 0.001), 0.0003), "") | E38: =IF(37<=Settings!$C$6, IF(Settings!$C$7="Random", CHOOSE(com.sun.star.sheet.addin.Analysis.getRandbetween(1,3), 64, 128, 256), 128), "") | F38: =IF(37<=Settings!$C$6, IF(Settings!$C$7="Random", CHOOSE(com.sun.star.sheet.addin.Analysis.getRandbetween(1,3), 1024, 2048, 4096), 2048), "") | G38: =IF(37<=Settings!$C$6, 500000, "") | H38: =IF(37<=Settings!$C$6, IF(Settings!$C$7="Random", CHOOSE(com.sun.star.sheet.addin.Analysis.getRandbetween(1,3), 42, 101, 2024), 42), "")
B39: =IF(38<=Settings!$C$6, "PushBlock", "") | C39: =IF(38<=Settings!$C$6, "PPO", "") | D39: =IF(38<=Settings!$C$6, IF(Settings!$C$7="Random", CHOOSE(com.sun.star.sheet.addin.Analysis.getRandbetween(1,4), 0.0001, 0.0003, 0.0005, 0.001), 0.0003), "") | E39: =IF(38<=Settings!$C$6, IF(Settings!$C$7="Random", CHOOSE(com.sun.star.sheet.addin.Analysis.getRandbetween(1,3), 64, 128, 256), 128), "") | F39: =IF(38<=Settings!$C$6, IF(Settings!$C$7="Random", CHOOSE(com.sun.star.sheet.addin.Analysis.getRandbetween(1,3), 1024, 2048, 4096), 2048), "") | G39: =IF(38<=Settings!$C$6, 500000, "") | H39: =IF(38<=Settings!$C$6, IF(Settings!$C$7="Random", CHOOSE(com.sun.star.sheet.addin.Analysis.getRandbetween(1,3), 42, 101, 2024), 42), "")
B40: =IF(39<=Settings!$C$6, "PushBlock", "") | C40: =IF(39<=Settings!$C$6, "PPO", "") | D40: =IF(39<=Settings!$C$6, IF(Settings!$C$7="Random", CHOOSE(com.sun.star.sheet.addin.Analysis.getRandbetween(1,4), 0.0001, 0.0003, 0.0005, 0.001), 0.0003), "") | E40: =IF(39<=Settings!$C$6, IF(Settings!$C$7="Random", CHOOSE(com.sun.star.sheet.addin.Analysis.getRandbetween(1,3), 64, 128, 256), 128), "") | F40: =IF(39<=Settings!$C$6, IF(Settings!$C$7="Random", CHOOSE(com.sun.star.sheet.addin.Analysis.getRandbetween(1,3), 1024, 2048, 4096), 2048), "") | G40: =IF(39<=Settings!$C$6, 500000, "") | H40: =IF(39<=Settings!$C$6, IF(Settings!$C$7="Random", CHOOSE(com.sun.star.sheet.addin.Analysis.getRandbetween(1,3), 42, 101, 2024), 42), "")
...

Sheet Settings
B2: PUSHBLOCK CONFIGURATOR CONTROLS
B3: Configure your experiment parameters here. The table in 'Training_Runs' updates automatically and is clean for direct CSV export.
B5: RUN CONTROLS
B6: Number of Training Runs (N) | C6: 20 | D6: Total number of active training rows in the data sheet (1 to 100)
B7: Generation Mode | C7: Random | D7: Choose 'Random' (auto-samples hyperparams) or 'Manual' (sets baseline values)

Sheet Prompt
A1: ### SYSTEM ROLE & CONTEXT - **Role:** You are an expert Python data engineer and spreadsheet automation specialist proficient with `openpyxl`. - **Project Context:** University ML-Agents benchmarking project (PushBlock environment, PPO algorithm). We need an interactive Excel configurator (`PushBlock_Training_Configurator_Secure_EN.xlsx`) that allows users to configure and auto-generate headless reinforcement learning experiment runs before feeding them into an automated Python execution pipeline. --- ### REQUIREMENTS ANALYSIS 1. **Interactive Control Dashboard (Header / Row Controls):** - Must allow the user to select the total number of training runs $N$ (integer between 1 and 100). - Must allow switching between two generation modes: * `Random`: Automatically samples valid candidate hyperparameter combinations using spreadsheet formulas. * `Manual`: Populates baseline defaults and lets the user choose values per row via drop-down menus. - Clean UI: Exclude unnecessary metadata fields (e.g., tester initials, output paths). Keep only Run Count ($N$) and Generation Mode. 2. **Schema & Dynamic Activation (Rows 1 to 100):** - The table must feature the standard 11 configuration columns: `run_id`, `environment_name`, `algorithm`, `learning_rate`, `batch_size`, `buffer_size`, `max_steps`, `random_seed`, `cpu_model`, `has_gpu`, `ram_gb`. - Dynamic Display Rule: Rows $r \le N$ are active and populated; rows $r > N$ must evaluate to empty strings (`""`) across all columns to keep unused rows completely blank. 3. **Strict Validation & Security Constraints (Fail-Safe & Anti-Tampering):** - All validation rules must use Excel's strict blocking style (`errorStyle="stop"` / `showErrorMessage=True`) with clear, descriptive English error messages. - **`run_id` (Column B):** Must remain strictly EMPTY. Validated via text length equal to 0. (IDs are generated dynamically at runtime by the execution script as `<prefix>-<timestamp>`). - **`environment_name` (Column C):** Immutable. Only permitted value is `"PushBlock"`. - **`algorithm` (Column D):** Immutable. Only permitted value is `"PPO"`. - **`learning_rate` (Column E):** Strict decimal validation between `0.0001` and `0.001`. - **`batch_size` (Column F):** Strict list validation allowing only `64, 128, 256`. - **`buffer_size` (Column G):** Strict list validation allowing only `1024, 2048, 4096`. - **`max_steps` (Column H):** Fixed integer cap locked to `500000`. - **`random_seed` (Column I):** Strict list validation allowing only `42, 101, 2024`. - **Hardware Columns (`cpu_model`, `has_gpu`, `ram_gb` in Cols J, K, L):** Must remain strictly EMPTY prior to execution. Validated via text length equal to 0 to prevent manual tampering. Hardware is detected and written automatically by the telemetry module at runtime. --- ### EXPLICIT IMPLEMENTATION INSTRUCTIONS Generate a standalone Python script using `openpyxl` that builds the `.xlsx` workbook from scratch: 1. **Workbook & Sheet Setup:** - Single worksheet titled `"Training_Configurations"`. - Enable gridlines: `ws.views.sheetView[0].showGridLines = True`. - Styling: Use a cohesive professional palette: * Dark Navy (`#1F4E78`) for primary banners and title. * Slate Blue (`#2F5597`) for table headers. * Soft Blue fill (`#D9E1F2`) for user-editable input cells ($C6, $C7). * Alternating zebra striping (`#F9FAFB`) on even active rows. * Thin light-gray borders (`#D9D9D9`) on all active cells. 2. **Top Control Panel (Rows 5 to 7):** - Row 5: Merged banner `B5:E5` titled `"1. RUN CONTROLS & GENERATION MODE"`. - Row 6: Label `"Number of Training Runs (N)"` in B6, editable value `20` in C6, helper description in `D6:G6`. * Apply integer DataValidation between 1 and 100 with error title `"Invalid Value"`. - Row 7: Label `"Generation Mode"` in B7, editable value `"Random"` in C7, helper description in `D7:G7`. * Apply list DataValidation `'"Random, Manual"'` with error title `"Invalid Mode"`. 3. **Table Header & Column Dimensions (Row 10 to 11):** - Row 10: Merged banner `B10:L10` titled `"2. TRAINING RUN CONFIGURATION MATRIX (11 COLUMNS)"`. - Row 11: 11 column headers with bold white text on Slate Blue fill. - Column widths: `A: 4, B: 14, C: 18, D: 12, E: 15, F: 13, G: 14, H: 13, I: 14, J: 20, K: 12, L: 12`. 4. **Formulas for Rows 12 to 111 (Indices 1 to 100):** - Col B (`run_id`): `""` (Always empty). - Col C (`environment_name`): `=IF(row_idx<=$C$6, "PushBlock", "")` - Col D (`algorithm`): `=IF(row_idx<=$C$6, "PPO", "")` - Col E (`learning_rate`): `=IF(row_idx<=$C$6, IF($C$7="Random", CHOOSE(RANDBETWEEN(1,4), 0.0001, 0.0003, 0.0005, 0.001), 0.0003), "")` * Number format: `'0.0000'`. - Col F (`batch_size`): `=IF(row_idx<=$C$6, IF($C$7="Random", CHOOSE(RANDBETWEEN(1,3), 64, 128, 256), 128), "")` - Col G (`buffer_size`): `=IF(row_idx<=$C$6, IF($C$7="Random", CHOOSE(RANDBETWEEN(1,3), 1024, 2048, 4096), 2048), "")` - Col H (`max_steps`): `=IF(row_idx<=$C$6, 500000, "")` - Col I (`random_seed`): `=IF(row_idx<=$C$6, IF($C$7="Random", CHOOSE(RANDBETWEEN(1,3), 42, 101, 2024), 42), "")` - Cols J, K, L (`cpu_model`, `has_gpu`, `ram_gb`): `""` (Always empty). 5. **Attach Strict DataValidations:** - Attach `dv_run_id` (`textLength == 0`) to `B12:B111`. - Attach `dv_env` (`list: '"PushBlock"'`) to `C12:C111`. - Attach `dv_algo` (`list: '"PPO"'`) to `D12:D111`. - Attach `dv_lr` (`decimal between 0.0001 and 0.001`) to `E12:E111`. - Attach `dv_bs` (`list: '"64, 128, 256"'`) to `F12:F111`. - Attach `dv_buf` (`list: '"1024, 2048, 4096"'`) to `G12:G111`. - Attach `dv_ms` (`list: '"500000"'`) to `H12:H111`. - Attach `dv_seed` (`list: '"42, 101, 2024"'`) to `I12:I111`. - Attach `dv_hw` (`textLength == 0`) to `J12:L111`. 6. **Execution Output:** - Save workbook as `PushBlock_Training_Configurator_Secure_EN.xlsx`. --- ### OUTPUT FORMAT Provide only the complete, self-contained Python script using `openpyxl`. Ensure the code executes cleanly with no missing imports or syntax errors.
